<?xml version="1.0" encoding="UTF-8"?>
<!-- Generated by org.testng.reporters.JUnitXMLReporter -->
<testsuite hostname="KAPIL" ignored="0" name="ExampleTest" tests="5" failures="1" timestamp="14 Aug 2018 06:53:36 GMT" time="38.423" errors="0">
  <testcase name="DemoQA" time="11.609" classname="Flows.LoginLogout"/>
  <testcase name="DemoQARegister" time="17.507" classname="Flows.LoginLogout"/>
  <testcase name="FirstTestCase" time="0.181" classname="Flows.LoginLogout2">
    <failure type="java.lang.AssertionError" message="Assertion Inside Catch expected [true] but found [false]">
      <![CDATA[java.lang.AssertionError: Assertion Inside Catch expected [true] but found [false]
at Keywords.KeywordRepository.loadURL(KeywordRepository.java:104)
at Flows.LoginLogout2.FirstTestCase(LoginLogout2.java:26)
... Removed 32 stack frames]]>
    </failure>
  </testcase> <!-- FirstTestCase -->
  <testcase name="SecondTestCase" time="0.0" classname="Flows.LoginLogout2"/>
  <testcase name="ThirdTestCase" time="0.0" classname="Flows.LoginLogout2"/>
</testsuite> <!-- ExampleTest -->
